<robot
  name="carmen">
  <link
    name="base_link">
    <inertial>
      <origin
        xyz="-6.93321136613356E-10 6.93716362132335E-10 0.0132471746322021"
        rpy="0 0 0" />
      <mass
        value="1.98561292253725" />
      <inertia
        ixx="0.00601736868309072"
        ixy="2.40683881157455E-11"
        ixz="1.48886272177373E-10"
        iyy="0.00601736846270403"
        iyz="-2.13579318154092E-10"
        izz="0.0117763337865827" />
    </inertial>
    <visual>
      <origin
        xyz="0 0 0"
        rpy="0 0 0" />
      <geometry>
        <mesh
          filename="package://carmen/meshes/base_link.STL" />
      </geometry>
      <material
        name="">
        <color
          rgba="0.898039215686275 0.917647058823529 0.929411764705882 1" />
      </material>
    </visual>
    <collision>
      <origin
        xyz="0 0 0"
        rpy="0 0 0" />
      <geometry>
        <mesh
          filename="package://carmen/meshes/base_link.STL" />
      </geometry>
    </collision>
  </link>
  <link
    name="link1">
    <inertial>
      <origin
        xyz="0.0053340185480945 0.0518962587154645 0.0871112780470915"
        rpy="0 0 0" />
      <mass
        value="3.98917551410872" />
      <inertia
        ixx="0.0204976274869031"
        ixy="-0.00500844158285609"
        ixz="0.000613020862720094"
        iyy="0.0674308285750242"
        iyz="0.0060340332342027"
        izz="0.0736275748962882" />
    </inertial>
    <visual>
      <origin
        xyz="0 0 0"
        rpy="0 0 0" />
      <geometry>
        <mesh
          filename="package://carmen/meshes/link1.STL" />
      </geometry>
      <material
        name="">
        <color
          rgba="0.898039215686275 0.917647058823529 0.929411764705882 1" />
      </material>
    </visual>
    <collision>
      <origin
        xyz="0 0 0"
        rpy="0 0 0" />
      <geometry>
        <mesh
          filename="package://carmen/meshes/link1.STL" />
      </geometry>
    </collision>
  </link>
  <joint
    name="joint1"
    type="continuous">
    <origin
      xyz="0 0 0"
      rpy="4.8302E-16 -1.8339E-30 -2.5751E-14" />
    <parent
      link="base_link" />
    <child
      link="link1" />
    <axis
      xyz="0 0 1" />
  </joint>
  <link
    name="link2">
    <inertial>
      <origin
        xyz="0.0552760005334134 -0.000155134727758161 0.137272101423964"
        rpy="0 0 0" />
      <mass
        value="1.11024651210595" />
      <inertia
        ixx="0.0243933351397536"
        ixy="-0.000272256620854632"
        ixz="0.000845053943793656"
        iyy="0.0258685421603902"
        iyz="-0.00277495204300085"
        izz="0.00272649367991527" />
    </inertial>
    <visual>
      <origin
        xyz="0 0 0"
        rpy="0 0 0" />
      <geometry>
        <mesh
          filename="package://carmen/meshes/link2.STL" />
      </geometry>
      <material
        name="">
        <color
          rgba="1 1 1 1" />
      </material>
    </visual>
    <collision>
      <origin
        xyz="0 0 0"
        rpy="0 0 0" />
      <geometry>
        <mesh
          filename="package://carmen/meshes/link2.STL" />
      </geometry>
    </collision>
  </link>
  <joint
    name="joint2"
    type="revolute">
    <origin
      xyz="-0.053205 0.10614 0.134"
      rpy="-4.9958E-16 -6.3954E-15 -3.7968E-15" />
    <parent
      link="link1" />
    <child
      link="link2" />
    <axis
      xyz="0.99453 -0.10445 0" />
    <limit
      lower="-1"
      upper="1"
      effort="0"
      velocity="0" />
  </joint>
  <link
    name="link3">
    <inertial>
      <origin
        xyz="0.0631275199888618 -0.0638795409644809 0.0506366520557763"
        rpy="0 0 0" />
      <mass
        value="0.861766136459663" />
      <inertia
        ixx="0.00437002005745678"
        ixy="0.000133236316419513"
        ixz="-0.00027427150546927"
        iyy="0.0015426412417731"
        iyz="-0.000204111806241616"
        izz="0.00447537484026787" />
    </inertial>
    <visual>
      <origin
        xyz="0 0 0"
        rpy="0 0 0" />
      <geometry>
        <mesh
          filename="package://carmen/meshes/link3.STL" />
      </geometry>
      <material
        name="">
        <color
          rgba="0.792156862745098 0.819607843137255 0.933333333333333 1" />
      </material>
    </visual>
    <collision>
      <origin
        xyz="0 0 0"
        rpy="0 0 0" />
      <geometry>
        <mesh
          filename="package://carmen/meshes/link3.STL" />
      </geometry>
    </collision>
  </link>
  <joint
    name="joint3"
    type="revolute">
    <origin
      xyz="-0.001749 -0.026227 0.40042"
      rpy="0 6.3954E-15 0" />
    <parent
      link="link2" />
    <child
      link="link3" />
    <axis
      xyz="0.99453 -0.10445 0" />
    <limit
      lower="-1"
      upper="1"
      effort="0"
      velocity="0" />
  </joint>
  <link
    name="link4">
    <inertial>
      <origin
        xyz="0.00163559573831511 0.189653738701388 0.00110555426614034"
        rpy="0 0 0" />
      <mass
        value="0.146288181972114" />
      <inertia
        ixx="0.00360467532988444"
        ixy="-3.49208798074887E-05"
        ixz="3.74348446235837E-06"
        iyy="0.000132730444634105"
        iyz="1.89580984601756E-05"
        izz="0.00372588980342106" />
    </inertial>
    <visual>
      <origin
        xyz="0 0 0"
        rpy="0 0 0" />
      <geometry>
        <mesh
          filename="package://carmen/meshes/link4.STL" />
      </geometry>
      <material
        name="">
        <color
          rgba="1 1 1 1" />
      </material>
    </visual>
    <collision>
      <origin
        xyz="0 0 0"
        rpy="0 0 0" />
      <geometry>
        <mesh
          filename="package://carmen/meshes/link4.STL" />
      </geometry>
    </collision>
  </link>
  <joint
    name="joint4"
    type="continuous">
    <origin
      xyz="0.067501 0.039558 0.068416"
      rpy="0 0 0" />
    <parent
      link="link3" />
    <child
      link="link4" />
    <axis
      xyz="-0.10445 -0.99449 -0.008915" />
  </joint>
  <link
    name="link5">
    <inertial>
      <origin
        xyz="-0.0389289069518734 0.0107114730948043 -0.00180818443937059"
        rpy="0 0 0" />
      <mass
        value="0.467258899920832" />
      <inertia
        ixx="0.000600122116157782"
        ixy="5.15752233141911E-05"
        ixz="-3.66501792464246E-06"
        iyy="0.000142296599259425"
        iyz="-4.12458151535323E-05"
        izz="0.000630999848320722" />
    </inertial>
    <visual>
      <origin
        xyz="0 0 0"
        rpy="0 0 0" />
      <geometry>
        <mesh
          filename="package://carmen/meshes/link5.STL" />
      </geometry>
      <material
        name="">
        <color
          rgba="0.792156862745098 0.819607843137255 0.933333333333333 1" />
      </material>
    </visual>
    <collision>
      <origin
        xyz="0 0 0"
        rpy="0 0 0" />
      <geometry>
        <mesh
          filename="package://carmen/meshes/link5.STL" />
      </geometry>
    </collision>
  </link>
  <joint
    name="joint5"
    type="revolute">
    <origin
      xyz="0.075297 0.33896 0.0043239"
      rpy="0 0 0" />
    <parent
      link="link4" />
    <child
      link="link5" />
    <axis
      xyz="-0.994 0.10468 -0.0316" />
    <limit
      lower="-1.57"
      upper="1.57"
      effort="0"
      velocity="0" />
  </joint>
  <link
    name="link6">
    <inertial>
      <origin
        xyz="0.0111325939791044 0.0139097993780345 0.00206227171785778"
        rpy="0 0 0" />
      <mass
        value="0.0519638203867105" />
      <inertia
        ixx="1.53938757630363E-05"
        ixy="-1.84323445567311E-06"
        ixz="-9.00401083462794E-07"
        iyy="2.0366732164192E-05"
        iyz="-1.85252359384799E-07"
        izz="2.00943933178844E-05" />
    </inertial>
    <visual>
      <origin
        xyz="0 0 0"
        rpy="0 0 0" />
      <geometry>
        <mesh
          filename="package://carmen/meshes/link6.STL" />
      </geometry>
      <material
        name="">
        <color
          rgba="0.752941176470588 0.752941176470588 0.752941176470588 1" />
      </material>
    </visual>
    <collision>
      <origin
        xyz="0 0 0"
        rpy="0 0 0" />
      <geometry>
        <mesh
          filename="package://carmen/meshes/link6.STL" />
      </geometry>
    </collision>
  </link>
  <joint
    name="joint6"
    type="continuous">
    <origin
      xyz="-0.028672 0.10222 -0.0094578"
      rpy="0 0 0" />
    <parent
      link="link5" />
    <child
      link="link6" />
    <axis
      xyz="0.10698 0.9908 -0.082926" />
  </joint>
</robot>